Workbook

Sheet README
A1: STORM SPLIT — Balance Model
A2: Single source of truth for every number in the game. Verse reads constants exported from here.
A5: HOW TO USE
A6: Blue cells | B6: Inputs and levers. These are the ONLY cells you edit. Change one and everything recalculates.
A7: Black cells | B7: Formulas. Do not overwrite — you will silently break the model.
A8: Green cells | B8: Links pulling a value from another sheet.
A9: Yellow fill | B9: Key assumptions worth arguing about before you build anything on them.
A11: SHEETS
A12: Tuning | B12: Master knobs. Start here. Almost every number downstream derives from this sheet.
A13: Towers | B13: The 5 base towers: purchase cost, damage, fire rate, range, whether they hit air.
A14: Tower Upgrades | B14: 75 rows — 5 towers x 3 paths x 5 tiers. Costs and stat multipliers per tier.
A15: Heroes | B15: 3 free heroes (Pistol, Assault Rifle, Shotgun): base gun and ability. Hero Upgrades: 3 paths x 5 tiers each.
A16: Mastery | B16: 20 permanent levels per hero, bought with Amber. Cheaper upgrades, cooldowns, head starts — never damage.
A17: Enemies | B17: The splitting ladder. Effective HP is the important derived column — read its note.
A18: Rounds | B18: All 40 rounds: composition, income, required DPS.
A19: Balance Check | B19: The validator. Tells you which rounds are unwinnable. Check this after every change.
A21: WORKFLOW
A22: 1 | B22: Tune a lever on the Tuning sheet.
A23: 2 | B23: Open Balance Check. Any round flagged TIGHT is one the player probably cannot afford to clear.
A24: 3 | B24: Adjust and repeat. Do not tune individual rounds until the curve is right.
A25: 4 | B25: Export the settled constants into the Verse constants file. Never hardcode a number in behavior scripts.
A27: WARNING
A28: Seeded values | B28: Every number here is a defensible starting point, not a tested one. They came from design
B29: reasoning, not playtesting. Expect to change most of them once the game is playable.

Sheet Tuning
A1: TUNING — master levers
A2: Every blue cell here drives the rest of the workbook. Change these, not the downstream sheets.
A4: Lever | B4: Value | C4: Unit | D4: What it controls
A5: ECONOMY
A6: Starting cash | B6: 450 | C6: cash | D6: Default: what players have before round 1 on Easy. Each level's own is Difficulty → Starting cash; the exporter checks Easy equals this.
A7: Starting lives | B7: 40 | C7: lives | D7: Not used by the game: lives come from Difficulty → Starting lives (Easy 40).
A8: Cash per effective HP | B8: 0.43 | C8: cash | D8: Cash per point of enemy HP destroyed, counting every split layer. Solved to make late rounds tight.
A9: Round bonus base | B9: 60 | C9: cash | D9: Flat end-of-round payment.
A10: Round bonus per round | B10: 1 | C10: cash | D10: Added per round number, so round 30 pays base + 30.
A11: TOWERS
A12: Tier cost growth | B12: 2.3 | C12: x | D12: Each upgrade tier costs this multiple of the tower's base cost, compounding.
A13: Tier damage growth | B13: 1.9 | C13: x | D13: Baseline damage multiple per tier before path character is applied.
A14: Sell refund | B14: 0.7 | C14: fraction | D14: Fraction of cash spent returned when selling a tower.
A15: ENEMIES
A16: Global HP scalar | B16: 1 | C16: x | D16: Multiplies every enemy's base HP. The fastest single difficulty dial.
A17: Round HP ramp | B17: 1.052 | C17: x | D17: Enemy HP compounds by this much per round. THIS is what makes late rounds hard, not enemy count.
A18: Max concurrent enemies | B18: 130 | C18: count | D18: Hard ceiling on a round's spawn count. Set by UEFN performance, not by design. Validate in phase 1.
A19: Global speed scalar | B19: 1 | C19: x | D19: Multiplies every enemy's speed.
A20: PLAYER
A21: Hero upgrade base cost | B21: 200 | C21: cash | D21: Tier 1 of any hero path. Picking a hero is free.
A22: Hero upgrade cost growth | B22: 2 | C22: x | D22: Each hero upgrade tier costs this multiple of the one before.
A24: PROGRESSION
A25: Multiplayer loss payout | B25: 5 | C25: amber | D25: Every player in a multiplayer match that ends without a clear. Clears pay the Difficulty sheet reward; solo losses pay nothing.
A26: Typical amber per match | B26: 50 | C26: amber | D26: Planning estimate only (Mastery "Matches to earn"). Not paid out by the game.
A27: Mastery cost base | B27: 25 | C27: amber | D27: Cost of mastery level 1.
A28: Mastery cost growth | B28: 1.18 | C28: x | D28: Compounding cost per mastery level to 20.
A29: VALIDATION
A30: Assumed spend on towers | B30: 0.75 | C30: fraction | D30: Share of cumulative cash a competent player puts into tower DPS.
A31: Expected efficiency | B31: 0.6 | C31: fraction | D31: Share of theoretical DPS actually landing, after targeting and travel-time losses.
A32: Rounds per tier | B32: 8 | C32: rounds | D32: How fast the reference build climbs tiers. Drives the rising cost per DPS.
A34: ABILITIES
A35: Line pierce reach | B35: 30 | C35: studs | D35: How far behind its target a line-piercing shot keeps hitting.
A36: Mark duration | B36: 3 | C36: s | D36: How long a Spotter mark lasts on an enemy.
A37: Bomblet damage | B37: 0.5 | C37: fraction | D37: Each cluster bomblet deals this share of the shell's damage.
A38: Bomblet spread | B38: 5 | C38: studs | D38: How far bomblets scatter from the shell.
A40: CO-OP
A41: Extra enemies per player | B41: 0.35 | C41: x | D41: Enemy count x grows by this for each player beyond the first (10 players = x4.15).
A42: Extra HP per player | B42: 0.08 | C42: x | D42: Enemy HP x grows by this for each player beyond the first.
A43: Starting cash per extra player | B43: 200 | C43: cash | D43: Added to the shared pot once for each player beyond the first, whenever they join.
A45: HERO
...

Sheet Towers
A1: TOWERS — base stats
A2: Purchase cost and tier-0 stats. Upgrade scaling lives on the Tower Upgrades sheet.
A4: Tower | B4: Role | C4: Cost | D4: Damage | E4: Fire rate /s | F4: Targets hit | G4: Base DPS | H4: Range (m) | I4: Hits air | J4: Income/round | K4: Design note | L4: Splash radius (m) | M4: Slow % | N4: Unlock cost (amber) | O4: Key | P4: Max HP | Q4: Heal /s | R4: Resist % | S4: Upgrade cost growth | T4: Untouchable | U4: On track | V4: Chains | W4: Birds | X4: Harpoons | Y4: Resin | Z4: Walkers
A5: Hunting Blind | B5: Cheap single-target DPS | C5: 200 | D5: 1 | E5: 3 | F5: 1 | G5: {=D5*E5*F5} | H5: 20 | I5: Yes | J5: 0 | K5: Spam early, never stop buying. The DPS baseline everything else is measured against. | L5: 0 | M5: 0 | N5: 0 | O5: SCOUT | P5: 100 | Q5: 0 | R5: 0
A6: Longshot Perch | B6: Global range, slow | C6: 350 | D6: 9 | E6: 0.45 | F6: 1 | G6: {=D6*E6*F6} | H6: 999 | I6: Yes | J6: 0 | K6: Range covers the whole map. Your answer to anything the ground towers cannot reach. | L6: 0 | M6: 0 | N6: 0 | O6: SNIPER | P6: 80 | Q6: 0 | R6: 0
A7: Mortar Pit | B7: Area damage, ground only | C7: 550 | D7: 5 | E7: 1 | F7: 3 | G7: {=D7*E7*F7} | H7: 18 | I7: No | J7: 0 | K7: Targets hit = average enemies caught per blast. Cannot hit air at all, by design. | L7: 6 | M7: 0 | N7: 0 | O7: GRENADIER | P7: 150 | Q7: 0 | R7: 0
A8: Tranq Station | B8: Tranquilizer darts: slows and knocks out | C8: 400 | D8: 0.5 | E8: 1 | F8: 4 | G8: {=D8*E8*F8} | H8: 12 | I8: Yes | J8: 0 | K8: Damage is nearly irrelevant. Its value is the slow, which multiplies every tower nearby. | L8: 6 | M8: 40 | N8: 100 | O8: CHILLER | P8: 120 | Q8: 0 | R8: 0
A9: Supply Camp | B9: Economy, no attack | C9: 1000 | D9: 0 | E9: 0 | F9: 0 | G9: {=D9*E9*F9} | H9: 20 | I9: No | J9: 150 | K9: Never shoots. Decides whether round 35 is affordable. | L9: 0 | M9: 0 | N9: 150 | O9: QUARTERMASTER | P9: 200 | Q9: 0 | R9: 0 | S9: 1.6
A10: Field Hospital | B10: Support: heals towers and hunters, no attack | C10: 450 | D10: 0 | E10: 0 | F10: 0 | G10: {=D10*E10*F10} | H10: 15 | I10: No | J10: 0 | K10: Never shoots. Heals standing towers and hunters in range; its paths revive trampled towers, drop med kits and toughen towers. | L10: 0 | M10: 0 | N10: 100 | O10: HOSPITAL | P10: 150 | Q10: 3 | R10: 0
A11: Armory | B11: Defence: damage resistance, no attack | C11: 600 | D11: 0 | E11: 0 | F11: 0 | G11: {=D11*E11*F11} | H11: 15 | I11: No | J11: 0 | K11: Never shoots. Towers and hunters in range take less damage; its paths add thorns, tower buffs and hunter handling. | L11: 0 | M11: 0 | N11: 150 | O11: ARMORY | P11: 250 | Q11: 0 | R11: 15
A13: Cost per DPS (Scout baseline) | C13: {=C5/G5} | D13: Cash needed to buy 1 DPS at tier 0. Balance Check uses this.
A15: Storm Coil | B15: Chain lightning: crowds and air | C15: 400 | D15: 6 | E15: 1 | F15: 1 | G15: =D15*E15*F15 | H15: 14 | I15: Yes | J15: 0 | K15: Each strike arcs from dino to dino (falloff per arc, breaks 1). Short own range. TOWERS_NEXT.md. | L15: 0 | M15: 0 | N15: 300 | O15: COIL | P15: 150 | Q15: 0 | R15: 0 | V15: Yes
A16: Falcon Roost | B16: Birds of prey: huge range, can't be damaged | C16: 400 | D16: 3 | E16: 1.33 | F16: 1 | G16: =D16*E16*F16 | H16: 40 | I16: Yes | J16: 0 | K16: Falcons fly out, dive and return. No HP: dinos ignore it, never repaired (DECISIONS #148). | L16: 0 | M16: 0 | N16: 200 | O16: FALCON | P16: 0 | Q16: 0 | R16: 0 | T16: Yes | W16: 2
A17: Tar Pit | B17: Tar on the track: slows and sinks, can't be damaged | C17: 450 | D17: 0 | E17: 0 | F17: 0 | G17: =D17*E17*F17 | H17: 12 | I17: No | J17: 0 | K17: Placed ON the track (DECISIONS #152); Range = the pool's length of track. No HP (#148). | L17: 0 | M17: 25 | N17: 250 | O17: TARPIT | P17: 0 | Q17: 0 | R17: 0 | T17: Yes | U17: Yes
A18: Harpoon Ballista | B18: The heaviest single hit: pierce-through | C18: 500 | D18: 12 | E18: 0.5 | F18: 1 | G18: =D18*E18*F18 | H18: 24 | I18: Yes | J18: 0 | K18: One heavy bolt every 2.5 s; its Spearhead path breaks several sizes (pierce-through). | L18: 0 | M18: 0 | N18: 300 | O18: BALLISTA | P18: 150 | Q18: 0 | R18: 0 | X18: Yes
A19: Amber Resin Cannon | B19: Control: resin slows, entombs and fossilizes | C19: 800 | D19: 2 | E19: 1 | F19: 1 | G19: =D19*E19*F19 | H19: 18 | I19: No | J19: 0 | K19: Resin globs: slows, entombs (hard stop), fossils. TOWERS_LATER.md. | L19: 0 | M19: 0 | N19: 500 | O19: RESIN | P19: 150 | Q19: 0 | R19: 0 | Y19: Yes
A20: Raptor Pen | B20: Tamed raptors: they run out, bite and come back | C20: 600 | D20: 10 | E20: 2.3 | F20: 1 | G20: =D20*E20*F20 | H20: 22 | I20: No | J20: 0 | K20: Tamed raptors sprint out, pounce, bite and come back; they can be bitten. TOWERS_LATER.md. | L20: 0 | M20: 0 | N20: 500 | O20: RAPTOR | P20: 150 | Q20: 0 | R20: 0 | Z20: 1
A21: Bone Totem | B21: Bones charge it: a roar, buffs or cash | C21: 600 | D21: 60 | E21: 0 | F21: 1 | G21: =D21*E21*F21 | H21: 24 | I21: Yes | J21: 0 | K21: Bones taken near it charge it; full = Spirit Roar (area, breaks 2). Never adds Bones to any score. TOWERS_LATER.md. | L21: 0 | M21: 0 | N21: 450 | O21: TOTEM | P21: 200 | Q21: 0 | R21: 0

Sheet Tower Upgrades
A1: TOWER UPGRADES — 11 towers x 3 paths x 5 tiers
A2: Multipliers are blue because they define each path's character. Costs are formulas off Tuning. Range x multiplies the tower's base range (range-focus paths only). Name is the tier's in-game name (full design: UPGRADES.md). Columns from 'Pierces armour' on are ability values, cumulative per tier; blank = none. A/B/C (PLAN Phase 9, DECISIONS #275): tiers 1-3 rows are cumulative; a tier-4 or tier-5 row is one option (Option A/B/C, Blurb = its card line, max 60 chars) and holds ONLY ITS OWN STEP over the tier below (x columns multiply, amounts take the higher, flags add, overrides replace; blank = no change). The exporter composes every build. New options are appended at the bottom.
A4: Tower | B4: Path | C4: Path focus | D4: Tier | E4: Upgrade cost | F4: Cumulative cost | G4: Damage x | H4: Rate x | I4: Targets x | J4: Resulting DPS | K4: Cost per DPS | L4: Range x | M4: Name | N4: Pierces armour | O4: Armoured x | P4: Boss x | Q4: Shots | R4: Line hits | S4: Splash x | T4: Mark % | U4: Stun (s) | V4: Stuns bosses | W4: Knockback (studs) | X4: Burn DPS | Y4: Burn (s) | Z4: Bomblets | AA4: Bomblet generations | AB4: Aura rate % | AC4: Aura damage % | AD4: Aura pierces armour | AE4: Slow % | AF4: Slow linger (s) | AG4: Slows bosses | AH4: Freeze every (s) | AI4: Freeze (s) | AJ4: Freeze damage | AK4: Freeze holds bosses | AL4: Brittle % | AM4: Strips armour | AN4: Income x | AO4: Interest % | AP4: Interest cap | AQ4: Chests | AR4: Chest cash | AS4: Upgrade discount % | AT4: Sell refund | AU4: Resist % | AV4: Thorns damage | AW4: Stuns biters (s) | AX4: Hunter recoil x | AY4: Hunter reload x | AZ4: Hunter spread x | BA4: Hunter fire rate % | BB4: Heal x | BC4: Revives | BD4: Revive speed x | BE4: Med kits | BF4: Med kit heal | BG4: Rescue beacon (respawn x) | BH4: Aura HP % | BI4: Last stand | BJ4: Size breaks | BK4: Arcs | BL4: Arc reach | BM4: Arc forks | BN4: Arc jumps | BO4: Power grid | BP4: Static % | BQ4: Judgement bolt | BR4: Grounding every (s) | BS4: Aura arc % | BT4: Birds | BU4: First dive x | BV4: Eagle | BW4: Murmuration | BX4: Boss mark % | BY4: Dive aura rate % | BZ4: Skewer | CA4: Tow line | CB4: Chain harpoons | CC4: Sink seconds | CD4: Sink cash | CE4: Sink chest cash | CF4: Eruption | CG4: Tracks slow % | CH4: Aura vs slowed % | CI4: Option | CJ4: Blurb | CK4: PvP effect | CL4: Raider slow % | CM4: Raider slow (s) | CN4: Raider damage | CO4: Bounty cash | CP4: Biter slow % | CQ4: Biter slow (s) | CR4: Field strike every (s) | CS4: Field strike x | CT4: Chain effects | CU4: Targets biggest | CV4: Entomb (s) | CW4: Entomb hits x | CX4: Entomb amp % | CY4: Entomb spread | CZ4: Entomb slow % | DA4: Entomb all every (s) | DB4: Boss entomb (s) | DC4: Send back (studs) | DD4: Fossil below % | DE4: Fossil rate % | DF4: Bounty fossils x | DG4: Heart every (fossils) | DH4: Seal (s) | DI4: Seal every (s) | DJ4: Seal heal % | DK4: Reflect damage | DL4: Wall (s) | DM4: Take-down mark % | DN4: Walkers | DO4: Walker HP x | DP4: Walker speed x | DQ4: Walker resist % | DR4: Walker respawn x | DS4: Hold (s) | DT4: Boss hold (s) | DU4: Flanking | DV4: Targets first | DW4: Hits air | DX4: Heals between rounds | DY4: Dodge | DZ4: Alpha | EA4: Swarm | EB4: Charge | EC4: Guard | ED4: Stun roar every (s) | EE4: Take-down stack % | EF4: Avenger x | EG4: Hunter damage % | EH4: Charge x | EI4: Hunter charge x | EJ4: Boss charge % | EK4: Bounty charge x | EL4: Charge needed x | EM4: Roar echoes | EN4: Roar whole track | EO4: Skulls | EP4: Full guard (s) | EQ4: Spirit hunters | ER4: Full cash | ES4: Payday cash | ET4: Treasure | EU4: Charge aura damage % | EV4: Hunter ability cooldown x | EW4: Side aura half | EX4: Bone cash | EY4: Bank cash per charge | EZ4: Finishing roar | FA4: Aura range %
A5: Hunting Blind | B5: Lookout | C5: range | D5: 1 | E5: {=ROUND('Towers'!$C$5*POWER('Tuning'!$B$12,D5),0)} | F5: {='Towers'!$C$5+E5} | G5: 1.3 | H5: 1.15 | I5: 1 | J5: {='Towers'!$G$5*G5*H5*I5} | K5: {=IF(J5=0,0,F5/J5)} | L5: 1.15 | M5: Keen Eyes
A6: Hunting Blind | B6: Lookout | C6: range | D6: 2 | E6: {=ROUND('Towers'!$C$5*POWER('Tuning'!$B$12,D6),0)} | F6: {=F5+E6} | G6: 1.69 | H6: 1.32 | I6: 1 | J6: {='Towers'!$G$5*G6*H6*I6} | K6: {=IF(J6=0,0,F6/J6)} | L6: 1.3 | M6: Spyglass
A7: Hunting Blind | B7: Lookout | C7: range | D7: 3 | E7: {=ROUND('Towers'!$C$5*POWER('Tuning'!$B$12,D7),0)} | F7: {=F6+E7} | G7: 2.2 | H7: 1.52 | I7: 1 | J7: {='Towers'!$G$5*G7*H7*I7} | K7: {=IF(J7=0,0,F7/J7)} | L7: 1.5 | M7: Flare Gun | AB7: 10
A8: Hunting Blind | B8: Lookout | C8: range | D8: 4 | E8: {=ROUND('Towers'!$C$5*POWER('Tuning'!$B$12,D8),0)} | F8: {=F7+E8} | G8: 1.3 | H8: 1.1513158 | I8: 1 | J8: {='Towers'!$G$5*G8*H8*I8} | K8: {=IF(J8=0,0,F8/J8)} | L8: 1.1666667 | M8: Watch Post | CI8: A | CJ8: Sees further, and shoots faster and harder
A9: Hunting Blind | B9: Lookout | C9: range | D9: 5 | E9: {=ROUND('Towers'!$C$5*POWER('Tuning'!$B$12,D9),0)} | F9: {=F8+E9} | G9: 1.2972028 | H9: 1.1485714 | I9: 1 | J9: {='Towers'!$G$5*G9*H9*I9} | K9: {=IF(J9=0,0,F9/J9)} | L9: 1.1428571 | M9: Signal Tower | AC9: 20 | AD9: Yes | CI9: A | CJ9: Towers in range hit harder and can hurt armour
A10: Hunting Blind | B10: Trigger Happy | C10: rate | D10: 1 | E10: {=ROUND('Towers'!$C$5*POWER('Tuning'!$B$12,D10),0)} | F10: {='Towers'!$C$5+E10} | G10: 1.35 | H10: 1.42 | I10: 1 | J10: {='Towers'!$G$5*G10*H10*I10} | K10: {=IF(J10=0,0,F10/J10)} | L10: 1 | M10: Quick Hands
A11: Hunting Blind | B11: Trigger Happy | C11: rate | D11: 2 | E11: {=ROUND('Towers'!$C$5*POWER('Tuning'!$B$12,D11),0)} | F11: {=F10+E11} | G11: 1.82 | H11: 2.02 | I11: 1 | J11: {='Towers'!$G$5*G11*H11*I11} | K11: {=IF(J11=0,0,F11/J11)} | L11: 1 | M11: Extended Mag
A12: Hunting Blind | B12: Trigger Happy | C12: rate | D12: 3 | E12: {=ROUND('Towers'!$C$5*POWER('Tuning'!$B$12,D12),0)} | F12: {=F11+E12} | G12: 2.46 | H12: 2.86 | I12: 1 | J12: {='Towers'!$G$5*G12*H12*I12} | K12: {=IF(J12=0,0,F12/J12)} | L12: 1 | M12: Double Tap | Q12: 2
A13: Hunting Blind | B13: Trigger Happy | C13: rate | D13: 4 | E13: {=ROUND('Towers'!$C$5*POWER('Tuning'!$B$12,D13),0)} | F13: {=F12+E13} | G13: 1.3495935 | H13: 1.4230769 | I13: 1 | J13: {='Towers'!$G$5*G13*H13*I13} | K13: {=IF(J13=0,0,F13/J13)} | L13: 1 | M13: Bullet Hose | CI13: A | CJ13: Fires much faster and hits harder
A14: Hunting Blind | B14: Trigger Happy | C14: rate | D14: 5 | E14: {=ROUND('Towers'!$C$5*POWER('Tuning'!$B$12,D14),0)} | F14: {=F13+E14} | G14: 1.3493976 | H14: 1.4176904 | I14: 1 | J14: {='Towers'!$G$5*G14*H14*I14} | K14: {=IF(J14=0,0,F14/J14)} | L14: 1 | M14: Lead Rain | Q14: 3 | CI14: A | CJ14: The fastest fire in the game
A15: Hunting Blind | B15: Hardliner | C15: damage | D15: 1 | E15: {=ROUND('Towers'!$C$5*POWER('Tuning'!$B$12,D15),0)} | F15: {='Towers'!$C$5+E15} | G15: 1.9 | H15: 1 | I15: 1 | J15: {='Towers'!$G$5*G15*H15*I15} | K15: {=IF(J15=0,0,F15/J15)} | L15: 1 | M15: Heavy Slugs
A16: Hunting Blind | B16: Hardliner | C16: damage | D16: 2 | E16: {=ROUND('Towers'!$C$5*POWER('Tuning'!$B$12,D16),0)} | F16: {=F15+E16} | G16: 3.61 | H16: 1 | I16: 1 | J16: {='Towers'!$G$5*G16*H16*I16} | K16: {=IF(J16=0,0,F16/J16)} | L16: 1 | M16: Armor Breaker | N16: Yes
A17: Hunting Blind | B17: Hardliner | C17: damage | D17: 3 | E17: {=ROUND('Towers'!$C$5*POWER('Tuning'!$B$12,D17),0)} | F17: {=F16+E17} | G17: 6.86 | H17: 1 | I17: 1 | J17: {='Towers'!$G$5*G17*H17*I17} | K17: {=IF(J17=0,0,F17/J17)} | L17: 1 | M17: Hollow Points | N17: Yes | O17: 2
A18: Hunting Blind | B18: Hardliner | C18: damage | D18: 4 | E18: {=ROUND('Towers'!$C$5*POWER('Tuning'!$B$12,D18),0)} | F18: {=F17+E18} | G18: 1.8994169 | H18: 1 | I18: 1 | J18: {='Towers'!$G$5*G18*H18*I18} | K18: {=IF(J18=0,0,F18/J18)} | L18: 1 | M18: Railshot | O18: 1 | R18: 3 | BJ18: 2 | CI18: A | CJ18: Each bullet goes through 3 dinos
A19: Hunting Blind | B19: Hardliner | C19: damage | D19: 5 | E19: {=ROUND('Towers'!$C$5*POWER('Tuning'!$B$12,D19),0)} | F19: {=F18+E19} | G19: 1.9002302 | H19: 1 | I19: 1 | J19: {='Towers'!$G$5*G19*H19*I19} | K19: {=IF(J19=0,0,F19/J19)} | L19: 1 | M19: Hide Buster | O19: 2 | P19: 4 | CI19: A | CJ19: Hits armoured dinos and bosses 4 times as hard
A20: Longshot Perch | B20: Deadeye | C20: targets | D20: 1 | E20: {=ROUND('Towers'!$C$6*POWER('Tuning'!$B$12,D20),0)} | F20: {='Towers'!$C$6+E20} | G20: 1.45 | H20: 1 | I20: 1.32 | J20: {='Towers'!$G$6*G20*H20*I20} | K20: {=IF(J20=0,0,F20/J20)} | L20: 1 | M20: Full Metal Jacket | R20: 2
A21: Longshot Perch | B21: Deadeye | C21: targets | D21: 2 | E21: {=ROUND('Towers'!$C$6*POWER('Tuning'!$B$12,D21),0)} | F21: {=F20+E21} | G21: 2.1 | H21: 1 | I21: 1.74 | J21: {='Towers'!$G$6*G21*H21*I21} | K21: {=IF(J21=0,0,F21/J21)} | L21: 1 | M21: Through-and-Through | N21: Yes | R21: 3
A22: Longshot Perch | B22: Deadeye | C22: targets | D22: 3 | E22: {=ROUND('Towers'!$C$6*POWER('Tuning'!$B$12,D22),0)} | F22: {=F21+E22} | G22: 3.05 | H22: 1 | I22: 2.3 | J22: {='Towers'!$G$6*G22*H22*I22} | K22: {=IF(J22=0,0,F22/J22)} | L22: 1 | M22: Ricochet | N22: Yes | R22: 4
A23: Longshot Perch | B23: Deadeye | C23: targets | D23: 4 | E23: {=ROUND('Towers'!$C$6*POWER('Tuning'!$B$12,D23),0)} | F23: {=F22+E23} | G23: 1.4491803 | H23: 1 | I23: 1.3217391 | J23: {='Towers'!$G$6*G23*H23*I23} | K23: {=IF(J23=0,0,F23/J23)} | L23: 1 | M23: Tungsten Core | R23: 6 | BJ23: 2 | CI23: A | CJ23: Shots go through more dinos, shrinking each 2 sizes
A24: Longshot Perch | B24: Deadeye | C24: targets | D24: 5 | E24: {=ROUND('Towers'!$C$6*POWER('Tuning'!$B$12,D24),0)} | F24: {=F23+E24} | G24: 2 | H24: 1 | I24: 1.3190789 | J24: {='Towers'!$G$6*G24*H24*I24} | K24: {=IF(J24=0,0,F24/J24)} | L24: 1 | M24: Linebreaker | R24: 10 | BJ24: 3 | CI24: A | CJ24: Each shot hits 10 dinos in a line, double damage
A25: Longshot Perch | B25: Spotter | C25: rate | D25: 1 | E25: {=ROUND('Towers'!$C$6*POWER('Tuning'!$B$12,D25),0)} | F25: {='Towers'!$C$6+E25} | G25: 1.35 | H25: 1.42 | I25: 1 | J25: {='Towers'!$G$6*G25*H25*I25} | K25: {=IF(J25=0,0,F25/J25)} | L25: 1 | M25: Steady Breath
A26: Longshot Perch | B26: Spotter | C26: rate | D26: 2 | E26: {=ROUND('Towers'!$C$6*POWER('Tuning'!$B$12,D26),0)} | F26: {=F25+E26} | G26: 1.82 | H26: 2.02 | I26: 1 | J26: {='Towers'!$G$6*G26*H26*I26} | K26: {=IF(J26=0,0,F26/J26)} | L26: 1 | M26: Bolt Racking
A27: Longshot Perch | B27: Spotter | C27: rate | D27: 3 | E27: {=ROUND('Towers'!$C$6*POWER('Tuning'!$B$12,D27),0)} | F27: {=F26+E27} | G27: 2.46 | H27: 2.86 | I27: 1 | J27: {='Towers'!$G$6*G27*H27*I27} | K27: {=IF(J27=0,0,F27/J27)} | L27: 1 | M27: Marked Target | T27: 25
A28: Longshot Perch | B28: Spotter | C28: rate | D28: 4 | E28: {=ROUND('Towers'!$C$6*POWER('Tuning'!$B$12,D28),0)} | F28: {=F27+E28} | G28: 1.3495935 | H28: 1.4230769 | I28: 1 | J28: {='Towers'!$G$6*G28*H28*I28} | K28: {=IF(J28=0,0,F28/J28)} | L28: 1 | M28: Game Spotter | T28: 35 | CI28: A | CJ28: Fires faster, and its mark hits harder
A29: Longshot Perch | B29: Spotter | C29: rate | D29: 5 | E29: {=ROUND('Towers'!$C$6*POWER('Tuning'!$B$12,D29),0)} | F29: {=F28+E29} | G29: 1.3493976 | H29: 1.4176904 | I29: 1 | J29: {='Towers'!$G$6*G29*H29*I29} | K29: {=IF(J29=0,0,F29/J29)} | L29: 1 | M29: Eye in the Sky | T29: 60 | AB29: 15 | CI29: A | CJ29: A bigger mark, and towers in range shoot faster
A30: Longshot Perch | B30: Big Bore | C30: damage | D30: 1 | E30: {=ROUND('Towers'!$C$6*POWER('Tuning'!$B$12,D30),0)} | F30: {='Towers'!$C$6+E30} | G30: 1.9 | H30: 1 | I30: 1 | J30: {='Towers'!$G$6*G30*H30*I30} | K30: {=IF(J30=0,0,F30/J30)} | L30: 1 | M30: Large Calibre
A31: Longshot Perch | B31: Big Bore | C31: damage | D31: 2 | E31: {=ROUND('Towers'!$C$6*POWER('Tuning'!$B$12,D31),0)} | F31: {=F30+E31} | G31: 3.61 | H31: 1 | I31: 1 | J31: {='Towers'!$G$6*G31*H31*I31} | K31: {=IF(J31=0,0,F31/J31)} | L31: 1 | M31: Bone Breaker | P31: 3 | BJ31: 2
A32: Longshot Perch | B32: Big Bore | C32: damage | D32: 3 | E32: {=ROUND('Towers'!$C$6*POWER('Tuning'!$B$12,D32),0)} | F32: {=F31+E32} | G32: 6.86 | H32: 1 | I32: 1 | J32: {='Towers'!$G$6*G32*H32*I32} | K32: {=IF(J32=0,0,F32/J32)} | L32: 1 | M32: Concussion Round | P32: 3 | U32: 0.4 | BJ32: 2
A33: Longshot Perch | B33: Big Bore | C33: damage | D33: 4 | E33: {=ROUND('Towers'!$C$6*POWER('Tuning'!$B$12,D33),0)} | F33: {=F32+E33} | G33: 1.8994169 | H33: 1 | I33: 1 | J33: {='Towers'!$G$6*G33*H33*I33} | K33: {=IF(J33=0,0,F33/J33)} | L33: 1 | M33: Punt Gun | P33: 1.6666667 | U33: 0.5 | BJ33: 3 | CI33: A | CJ33: Huge shots that stun and shrink a dino 3 sizes
A34: Longshot Perch | B34: Big Bore | C34: damage | D34: 5 | E34: {=ROUND('Towers'!$C$6*POWER('Tuning'!$B$12,D34),0)} | F34: {=F33+E34} | G34: 1.9002302 | H34: 1 | I34: 1 | J34: {='Towers'!$G$6*G34*H34*I34} | K34: {=IF(J34=0,0,F34/J34)} | L34: 1 | M34: Extinction Round | P34: 2 | U34: 0.8 | V34: Yes | BJ34: 4 | CI34: A | CJ34: 10 times damage to bosses, and stuns them
A35: Mortar Pit | B35: Blast | C35: targets | D35: 1 | E35: {=ROUND('Towers'!$C$7*POWER('Tuning'!$B$12,D35),0)} | F35: {='Towers'!$C$7+E35} | G35: 1.45 | H35: 1 | I35: 1.32 | J35: {='Towers'!$G$7*G35*H35*I35} | K35: {=IF(J35=0,0,F35/J35)} | L35: 1 | M35: Bigger Bang | S35: 1.25
A36: Mortar Pit | B36: Blast | C36: targets | D36: 2 | E36: {=ROUND('Towers'!$C$7*POWER('Tuning'!$B$12,D36),0)} | F36: {=F35+E36} | G36: 2.1 | H36: 1 | I36: 1.74 | J36: {='Towers'!$G$7*G36*H36*I36} | K36: {=IF(J36=0,0,F36/J36)} | L36: 1 | M36: Shrapnel | S36: 1.4
A37: Mortar Pit | B37: Blast | C37: targets | D37: 3 | E37: {=ROUND('Towers'!$C$7*POWER('Tuning'!$B$12,D37),0)} | F37: {=F36+E37} | G37: 3.05 | H37: 1 | I37: 2.3 | J37: {='Towers'!$G$7*G37*H37*I37} | K37: {=IF(J37=0,0,F37/J37)} | L37: 1 | M37: Napalm | S37: 1.5 | X37: 1 | Y37: 3
A38: Mortar Pit | B38: Blast | C38: targets | D38: 4 | E38: {=ROUND('Towers'!$C$7*POWER('Tuning'!$B$12,D38),0)} | F38: {=F37+E38} | G38: 1.4491803 | H38: 1 | I38: 1.3217391 | J38: {='Towers'!$G$7*G38*H38*I38} | K38: {=IF(J38=0,0,F38/J38)} | L38: 1 | M38: Firestorm | S38: 1.0666667 | X38: 2 | Y38: 4 | CI38: A | CJ38: Bigger blasts that leave dinos burning
A39: Mortar Pit | B39: Blast | C39: targets | D39: 5 | E39: {=ROUND('Towers'!$C$7*POWER('Tuning'!$B$12,D39),0)} | F39: {=F38+E39} | G39: 1.4502262 | H39: 1 | I39: 1.3190789 | J39: {='Towers'!$G$7*G39*H39*I39} | K39: {=IF(J39=0,0,F39/J39)} | L39: 1 | M39: Scorched Earth | S39: 1.125 | X39: 4 | Y39: 6 | CI39: A | CJ39: Leaves a long burning stretch of track
A40: Mortar Pit | B40: Cluster | C40: targets | D40: 1 | E40: {=ROUND('Towers'!$C$7*POWER('Tuning'!$B$12,D40),0)} | F40: {='Towers'!$C$7+E40} | G40: 1.45 | H40: 1 | I40: 1.32 | J40: {='Towers'!$G$7*G40*H40*I40} | K40: {=IF(J40=0,0,F40/J40)} | L40: 1 | M40: Cluster Shell | Z40: 3 | AA40: 1
A41: Mortar Pit | B41: Cluster | C41: targets | D41: 2 | E41: {=ROUND('Towers'!$C$7*POWER('Tuning'!$B$12,D41),0)} | F41: {=F40+E41} | G41: 2.1 | H41: 1 | I41: 1.74 | J41: {='Towers'!$G$7*G41*H41*I41} | K41: {=IF(J41=0,0,F41/J41)} | L41: 1 | M41: Rapid Loader | Z41: 3 | AA41: 1
...

Sheet Heroes
A1: HEROES — hunter classes, free to pick once owned; each is a weapon plus an ability (HEROES.md)
A2: Base gun before any upgrade. Hero Upgrades multiplies or overrides these. More heroes = more rows.
A4: Key | B4: Hero | C4: Role | D4: Ability | E4: Damage | F4: Fire rate /s | G4: Fire mode | H4: Magazine | I4: Reload (s) | J4: Pellets | K4: Spread (deg) | L4: Recoil per shot (deg) | M4: Recoil max (deg) | N4: Recoil recovery (deg/s) | O4: Range (m) | P4: Pierces armour | Q4: Hits air | R4: Splash radius (m) | S4: Ability power | T4: Ability (s) | U4: Ability radius (m) | V4: Ability cooldown (s) | W4: Note | X4: Unlock cost (amber) | Y4: Weapon | Z4: Ability kind
A5: PISTOL | B5: Tracker | C5: Precision | D5: Tracking Dart | E5: 1.5 | F5: 4 | G5: semi | H5: 12 | I5: 1.2 | J5: 1 | K5: 0.5 | L5: 1.2 | M5: 6 | N5: 12 | O5: 55 | P5: No | Q5: Yes | R5: 0 | S5: 50 | T5: 8 | U5: 0 | V5: 45 | W5: Mark: power = +% damage taken, (s) = length. Passes to splits. | X5: 0 | Y5: Revolver | Z5: MARK
A6: RIFLE | B6: Big Game Hunter | C6: Sustained | D6: Rally Cry | E6: 0.8 | F6: 8 | G6: auto | H6: 30 | I6: 2 | J6: 1 | K6: 1 | L6: 0.6 | M6: 8 | N6: 10 | O6: 40 | P6: No | Q6: Yes | R6: 0 | S6: 40 | T6: 10 | U6: 25 | V6: 45 | W6: Overdrive: your fire rate x Tuning, towers in radius +power% fire rate. | X6: 75 | Y6: Hunting Rifle | Z6: OVERDRIVE
A7: SHOTGUN | B7: Brush Beater | C7: Close range | D7: Flare Strike | E7: 0.8 | F7: 1.2 | G7: semi | H7: 6 | I7: 2.2 | J7: 6 | K7: 7 | L7: 3 | M7: 8 | N7: 8 | O7: 25 | P7: No | Q7: No | R7: 0 | S7: 30 | T7: 2 | U7: 10 | V7: 45 | W7: Airburst: power = damage, (s) = stun, radius on the track. | X7: 75 | Y7: Shotgun | Z7: AIRBURST
A8: MEDIC | B8: Field Medic | C8: Support | D8: Triage Kit | E8: 1 | F8: 3 | G8: semi | H8: 10 | I8: 1.8 | J8: 1 | K8: 0.8 | L8: 1 | M8: 6 | N8: 12 | O8: 45 | P8: No | Q8: Yes | R8: 0 | S8: 40 | T8: 0 | U8: 20 | V8: 35 | W8: Heal: power = HP healed (flat, not scaled by hero levels) to you and every hunter within radius. Triage adds tower repair (Patch Up) and Second Wind guard. | X8: 75 | Y8: Lever-Action Carbine | Z8: HEAL

Sheet Hero Upgrades
A1: HERO UPGRADES — 4 heroes x 3 paths x 6 tiers (HEROES.md)
A2: Effect columns are cumulative per tier (like Tower Upgrades); blank = no change. x columns multiply the hero's base; Fire mode / Guns / Pellets / Pierce / Bounces override it. Crossover rule as towers: two paths, one past tier 2. Damage is per shot: pellets share the hero's base damage x its base pellet count, so more pellets spread the same damage wider and a slug concentrates it. Ignite: an enemy hit burns for Ignite (s), then takes one tick of Ignite tick x the whole shot's damage. The fire passes to the enemy's split children, so a Brute shot down to Husks sees them burn out together. A/B/C (PLAN Phase 9, DECISIONS #275): tiers 1-3 rows are cumulative; a tier-4 or tier-5 row is one option (Option A/B/C, Blurb = its card line, max 60 chars) and holds ONLY ITS OWN STEP over the tier below; so does tier 6 (no option) (x columns multiply, amounts take the higher, flags add, overrides replace; blank = no change). The exporter composes every build. New options are appended at the bottom.
A4: Hero | B4: Path | C4: Focus | D4: Tier | E4: Name | F4: Cost | G4: Fire rate x | H4: Magazine x | I4: Reload x | J4: Spread x | K4: Recoil x | L4: Range x | M4: Damage x | N4: Fire mode | O4: Burst count | P4: Guns | Q4: Pellets | R4: Shots per trigger | S4: Pierce | T4: Bounces | U4: Pierces armour | V4: Hits air | W4: Burn DPS | X4: Burn (s) | Y4: Splash radius (m) | Z4: Knockback (studs) | AA4: Mark % | AB4: Marked damage x | AC4: Ability cooldown x | AD4: Belt fed | AE4: Still recoil x | AF4: Spin-up x | AG4: Scope | AH4: Ignite (s) | AI4: Ignite tick (x shot) | AJ4: Heal x | AK4: Heal radius x | AL4: Heal repairs towers | AM4: Guard % | AN4: Guard (s) | AO4: Slow on hit % | AP4: Slow on hit (s) | AQ4: Jaw lock (s) | AR4: Jaw lock spread (studs) | AS4: Size breaks | AT4: Burn patch reach (studs) | AU4: Staggered reload | AV4: Ricochet reload (rounds) | AW4: Burst recoil reset | AX4: Spun-up belt | AY4: Still spread x | AZ4: Scoped spread x | BA4: Ability charges | BB4: Option | BC4: Blurb | BD4: Heal regen HP/s | BE4: Heal regen (s) | BF4: One round per trigger
A5: Tracker | B5: Gunslinger | C5: handling | D5: 1 | E5: Quick Draw | F5: =ROUND(Tuning!$B$21*POWER(Tuning!$B$22,D5-1),0) | G5: 1.15 | I5: 0.9
A6: Tracker | B6: Gunslinger | C6: handling | D6: 2 | E6: Hair Trigger | F6: =ROUND(Tuning!$B$21*POWER(Tuning!$B$22,D6-1),0) | G6: 1.3 | I6: 0.85
A7: Tracker | B7: Gunslinger | C7: handling | D7: 3 | E7: Dual Pistols | F7: =ROUND(Tuning!$B$21*POWER(Tuning!$B$22,D7-1),0) | G7: 1.3 | I7: 0.85 | P7: 2
A8: Tracker | B8: Gunslinger | C8: handling | D8: 4 | E8: Fan the Hammer | F8: =ROUND(Tuning!$B$21*POWER(Tuning!$B$22,D8-1),0) | G8: 1.2307692 | I8: 0.94117647 | BB8: A | BC8: Fires faster and reloads quicker
A9: Tracker | B9: Gunslinger | C9: handling | D9: 5 | E9: Akimbo Frenzy | F9: =ROUND(Tuning!$B$21*POWER(Tuning!$B$22,D9-1),0) | G9: 1.25 | H9: 1.5 | I9: 0.875 | N9: auto | BB9: A | BC9: Both guns go full-auto
A10: Tracker | B10: Marksman | C10: accuracy | D10: 1 | E10: Match Barrel | F10: =ROUND(Tuning!$B$21*POWER(Tuning!$B$22,D10-1),0) | J10: 0.6
A11: Tracker | B11: Marksman | C11: accuracy | D11: 2 | E11: Steady Hands | F11: =ROUND(Tuning!$B$21*POWER(Tuning!$B$22,D11-1),0) | J11: 0.5 | K11: 0.6
A12: Tracker | B12: Marksman | C12: accuracy | D12: 3 | E12: Scope | F12: =ROUND(Tuning!$B$21*POWER(Tuning!$B$22,D12-1),0) | J12: 0.3 | K12: 0.5 | L12: 1.6 | AG12: Yes
A13: Tracker | B13: Marksman | C13: accuracy | D13: 4 | E13: Hollow Tips | F13: =ROUND(Tuning!$B$21*POWER(Tuning!$B$22,D13-1),0) | J13: 1 | K13: 1 | L13: 1 | U13: Yes | BB13: A | BC13: Shots pierce armour
A14: Tracker | B14: Marksman | C14: accuracy | D14: 5 | E14: Deadshot | F14: =ROUND(Tuning!$B$21*POWER(Tuning!$B$22,D14-1),0) | J14: 0.83333333 | K14: 0.8 | L14: 1.125 | AB14: 3 | BB14: A | BC14: Triple damage to marked dinos
A15: Tracker | B15: Trick Shot | C15: utility | D15: 1 | E15: Speed Loader | F15: =ROUND(Tuning!$B$21*POWER(Tuning!$B$22,D15-1),0) | I15: 0.6
A16: Tracker | B16: Trick Shot | C16: utility | D16: 2 | E16: Extended Mag | F16: =ROUND(Tuning!$B$21*POWER(Tuning!$B$22,D16-1),0) | H16: 1.6 | I16: 0.6
A17: Tracker | B17: Trick Shot | C17: utility | D17: 3 | E17: Ricochet | F17: =ROUND(Tuning!$B$21*POWER(Tuning!$B$22,D17-1),0) | H17: 1.6 | I17: 0.6 | T17: 1
A18: Tracker | B18: Trick Shot | C18: utility | D18: 4 | E18: Quick Dart | F18: =ROUND(Tuning!$B$21*POWER(Tuning!$B$22,D18-1),0) | H18: 1 | I18: 1 | AC18: 0.6 | BB18: A | BC18: Your Tracking Dart is ready again sooner
A19: Tracker | B19: Trick Shot | C19: utility | D19: 5 | E19: Chain Shot | F19: =ROUND(Tuning!$B$21*POWER(Tuning!$B$22,D19-1),0) | H19: 1 | I19: 1 | T19: 4 | AC19: 1 | BB19: A | BC19: Shots bounce 4 times
A20: Big Game Hunter | B20: Stalker | C20: control | D20: 1 | E20: Foregrip | F20: =ROUND(Tuning!$B$21*POWER(Tuning!$B$22,D20-1),0) | K20: 0.75
A21: Big Game Hunter | B21: Stalker | C21: control | D21: 2 | E21: Compensator | F21: =ROUND(Tuning!$B$21*POWER(Tuning!$B$22,D21-1),0) | J21: 0.8 | K21: 0.55
A22: Big Game Hunter | B22: Stalker | C22: control | D22: 3 | E22: Burst Fire | F22: =ROUND(Tuning!$B$21*POWER(Tuning!$B$22,D22-1),0) | G22: 1.4 | J22: 0.6 | K22: 0.4 | N22: burst | O22: 3
A23: Big Game Hunter | B23: Stalker | C23: control | D23: 4 | E23: Trigger Discipline | F23: =ROUND(Tuning!$B$21*POWER(Tuning!$B$22,D23-1),0) | G23: 1 | J23: 1 | K23: 0.75 | L23: 1.3 | BB23: A | BC23: Less kick and longer reach
A24: Big Game Hunter | B24: Stalker | C24: control | D24: 5 | E24: Precision Burst | F24: =ROUND(Tuning!$B$21*POWER(Tuning!$B$22,D24-1),0) | G24: 1.0714286 | J24: 0.5 | K24: 0.83333333 | L24: 1.1538462 | M24: 1.3 | O24: 4 | BB24: A | BC24: 4-round bursts with a much tighter grouping
A25: Big Game Hunter | B25: Heavy | C25: sustain | D25: 1 | E25: Drum Mag | F25: =ROUND(Tuning!$B$21*POWER(Tuning!$B$22,D25-1),0) | H25: 1.7
A26: Big Game Hunter | B26: Heavy | C26: sustain | D26: 2 | E26: Fast Hands | F26: =ROUND(Tuning!$B$21*POWER(Tuning!$B$22,D26-1),0) | H26: 1.7 | I26: 0.65
A27: Big Game Hunter | B27: Heavy | C27: sustain | D27: 3 | E27: Belt Fed | F27: =ROUND(Tuning!$B$21*POWER(Tuning!$B$22,D27-1),0) | H27: 1.7 | I27: 0.65 | AD27: Yes
A28: Big Game Hunter | B28: Heavy | C28: sustain | D28: 4 | E28: Bipod | F28: =ROUND(Tuning!$B$21*POWER(Tuning!$B$22,D28-1),0) | H28: 1 | I28: 1 | AE28: 0.3 | BB28: A | BC28: Much less kick while you stand still
A29: Big Game Hunter | B29: Heavy | C29: sustain | D29: 5 | E29: Spin-Up | F29: =ROUND(Tuning!$B$21*POWER(Tuning!$B$22,D29-1),0) | H29: 1.2941176 | I29: 1 | AE29: 1 | AF29: 2.5 | BB29: A | BC29: Fire rate climbs while you hold the trigger
A30: Big Game Hunter | B30: Special Ammo | C30: rounds | D30: 1 | E30: Tracer Rounds | F30: =ROUND(Tuning!$B$21*POWER(Tuning!$B$22,D30-1),0) | AA30: 10
A31: Big Game Hunter | B31: Special Ammo | C31: rounds | D31: 2 | E31: Incendiary | F31: =ROUND(Tuning!$B$21*POWER(Tuning!$B$22,D31-1),0) | W31: 1 | X31: 2 | AA31: 10
A32: Big Game Hunter | B32: Special Ammo | C32: rounds | D32: 3 | E32: AP Rounds | F32: =ROUND(Tuning!$B$21*POWER(Tuning!$B$22,D32-1),0) | U32: Yes | W32: 1 | X32: 2 | AA32: 10
A33: Big Game Hunter | B33: Special Ammo | C33: rounds | D33: 4 | E33: Hot Load | F33: =ROUND(Tuning!$B$21*POWER(Tuning!$B$22,D33-1),0) | L33: 1.2 | M33: 1.25 | BB33: A | BC33: Hits harder and reaches further
A34: Big Game Hunter | B34: Special Ammo | C34: rounds | D34: 5 | E34: Explosive Tips | F34: =ROUND(Tuning!$B$21*POWER(Tuning!$B$22,D34-1),0) | L34: 1 | M34: 1 | Y34: 4 | BB34: A | BC34: Shots burst with a small splash
A35: Brush Beater | B35: Slug | C35: reach | D35: 1 | E35: Slug Rounds | F35: =ROUND(Tuning!$B$21*POWER(Tuning!$B$22,D35-1),0) | J35: 0.1 | L35: 1.8 | M35: 0.67 | Q35: 1 | S35: 2
A36: Brush Beater | B36: Slug | C36: reach | D36: 2 | E36: Rifled Barrel | F36: =ROUND(Tuning!$B$21*POWER(Tuning!$B$22,D36-1),0) | J36: 0.1 | L36: 2.2 | M36: 0.67 | Q36: 1 | S36: 2 | V36: Yes
A37: Brush Beater | B37: Slug | C37: reach | D37: 3 | E37: Sabot | F37: =ROUND(Tuning!$B$21*POWER(Tuning!$B$22,D37-1),0) | J37: 0.1 | L37: 2.2 | M37: 0.67 | Q37: 1 | S37: 2 | U37: Yes | V37: Yes
A38: Brush Beater | B38: Slug | C38: reach | D38: 4 | E38: Long Barrel | F38: =ROUND(Tuning!$B$21*POWER(Tuning!$B$22,D38-1),0) | J38: 0.8 | L38: 1.1818182 | M38: 1 | S38: 3 | BB38: A | BC38: Tighter, longer slugs that go through 3 dinos
A39: Brush Beater | B39: Slug | C39: reach | D39: 5 | E39: Railslug | F39: =ROUND(Tuning!$B$21*POWER(Tuning!$B$22,D39-1),0) | J39: 0.625 | L39: 1.1538462 | M39: 1.4925373 | S39: 6 | BB39: A | BC39: Slugs go through 6 dinos
A40: Brush Beater | B40: Buckshot | C40: crowds | D40: 1 | E40: Tight Choke | F40: =ROUND(Tuning!$B$21*POWER(Tuning!$B$22,D40-1),0) | J40: 0.7
A41: Brush Beater | B41: Buckshot | C41: crowds | D41: 2 | E41: Extra Pellets | F41: =ROUND(Tuning!$B$21*POWER(Tuning!$B$22,D41-1),0) | J41: 0.7 | Q41: 9
...

Sheet Mastery
A1: HERO MASTERY — permanent, per hero
A2: Bought with Amber. Head starts and unlocks only — never gun damage multipliers.
A4: Level | B4: Amber cost | C4: Cumulative amber | D4: Matches to earn | E4: Unlock at this level | F4: Upgrade discount % | G4: Ability cooldown x | H4: Free first upgrade | I4: Crossover cap | J4: Pick-up reach + | K4: Heal per round + | L4: Respawn x | M4: Repair cost x
A5: 1 | B5: {=ROUND('Tuning'!$B$27*POWER('Tuning'!$B$28,A5-1),0)} | C5: {=B5} | D5: =ROUND(C5/Tuning!$B$26,1) | E5: -5% on this hero's upgrade costs | F5: 5 | G5: 1 | H5: No | I5: 2 | L5: 1 | M5: 1
A6: 2 | B6: {=ROUND('Tuning'!$B$27*POWER('Tuning'!$B$28,A6-1),0)} | C6: {=C5+B6} | D6: =ROUND(C6/Tuning!$B$26,1) | E6: -10% cumulative | F6: 10 | G6: 1 | H6: No | I6: 2 | L6: 1 | M6: 1
A7: 3 | B7: {=ROUND('Tuning'!$B$27*POWER('Tuning'!$B$28,A7-1),0)} | C7: {=C6+B7} | D7: =ROUND(C7/Tuning!$B$26,1) | E7: -15% cumulative | F7: 15 | G7: 1 | H7: No | I7: 2 | L7: 1 | M7: 1
A8: 4 | B8: {=ROUND('Tuning'!$B$27*POWER('Tuning'!$B$28,A8-1),0)} | C8: {=C7+B8} | D8: =ROUND(C8/Tuning!$B$26,1) | E8: -20% cumulative (cap on cost reduction) | F8: 20 | G8: 1 | H8: No | I8: 2 | L8: 1 | M8: 1
A9: 5 | B9: {=ROUND('Tuning'!$B$27*POWER('Tuning'!$B$28,A9-1),0)} | C9: {=C8+B9} | D9: =ROUND(C9/Tuning!$B$26,1) | E9: Ability cooldown -15% | F9: 20 | G9: 0.85 | H9: No | I9: 2 | L9: 1 | M9: 1
A10: 6 | B10: {=ROUND('Tuning'!$B$27*POWER('Tuning'!$B$28,A10-1),0)} | C10: {=C9+B10} | D10: =ROUND(C10/Tuning!$B$26,1) | E10: Long Arms I: pick up chests and med kits from 2 studs away | F10: 20 | G10: 0.85 | H10: No | I10: 2 | J10: 2 | L10: 1 | M10: 1
A11: 7 | B11: {=ROUND('Tuning'!$B$27*POWER('Tuning'!$B$28,A11-1),0)} | C11: {=C10+B11} | D11: =ROUND(C11/Tuning!$B$26,1) | E11: First Aid I: heal 5 more HP when a round is cleared | F11: 20 | G11: 0.85 | H11: No | I11: 2 | J11: 2 | K11: 5 | L11: 1 | M11: 1
A12: 8 | B12: {=ROUND('Tuning'!$B$27*POWER('Tuning'!$B$28,A12-1),0)} | C12: {=C11+B12} | D12: =ROUND(C12/Tuning!$B$26,1) | E12: Back in Action I: respawn 10% sooner | F12: 20 | G12: 0.85 | H12: No | I12: 2 | J12: 2 | K12: 5 | L12: 0.9 | M12: 1
A13: 9 | B13: {=ROUND('Tuning'!$B$27*POWER('Tuning'!$B$28,A13-1),0)} | C13: {=C12+B13} | D13: =ROUND(C13/Tuning!$B$26,1) | E13: Handyman I: repairs cost 5% less | F13: 20 | G13: 0.85 | H13: No | I13: 2 | J13: 2 | K13: 5 | L13: 0.9 | M13: 0.95
A14: 10 | B14: {=ROUND('Tuning'!$B$27*POWER('Tuning'!$B$28,A14-1),0)} | C14: {=C13+B14} | D14: =ROUND(C14/Tuning!$B$26,1) | E14: Start every match with your first upgrade free, plus this hero's mastery-10 ability perk | F14: 20 | G14: 0.85 | H14: Yes | I14: 2 | J14: 2 | K14: 5 | L14: 0.9 | M14: 0.95
A15: 11 | B15: {=ROUND('Tuning'!$B$27*POWER('Tuning'!$B$28,A15-1),0)} | C15: {=C14+B15} | D15: =ROUND(C15/Tuning!$B$26,1) | E15: Long Arms II: pick up chests and med kits from 4 studs away | F15: 20 | G15: 0.85 | H15: Yes | I15: 2 | J15: 4 | K15: 5 | L15: 0.9 | M15: 0.95
A16: 12 | B16: {=ROUND('Tuning'!$B$27*POWER('Tuning'!$B$28,A16-1),0)} | C16: {=C15+B16} | D16: =ROUND(C16/Tuning!$B$26,1) | E16: First Aid II: heal 10 more HP when a round is cleared | F16: 20 | G16: 0.85 | H16: Yes | I16: 2 | J16: 4 | K16: 10 | L16: 0.9 | M16: 0.95
A17: 13 | B17: {=ROUND('Tuning'!$B$27*POWER('Tuning'!$B$28,A17-1),0)} | C17: {=C16+B17} | D17: =ROUND(C17/Tuning!$B$26,1) | E17: Back in Action II: respawn 20% sooner | F17: 20 | G17: 0.85 | H17: Yes | I17: 2 | J17: 4 | K17: 10 | L17: 0.8 | M17: 0.95
A18: 14 | B18: {=ROUND('Tuning'!$B$27*POWER('Tuning'!$B$28,A18-1),0)} | C18: {=C17+B18} | D18: =ROUND(C18/Tuning!$B$26,1) | E18: Handyman II: repairs cost 10% less | F18: 20 | G18: 0.85 | H18: Yes | I18: 2 | J18: 4 | K18: 10 | L18: 0.8 | M18: 0.9
A19: 15 | B19: {=ROUND('Tuning'!$B$27*POWER('Tuning'!$B$28,A19-1),0)} | C19: {=C18+B19} | D19: =ROUND(C19/Tuning!$B$26,1) | E19: Ability cooldown -30%, plus this hero's mastery-15 ability perk | F19: 20 | G19: 0.7 | H19: Yes | I19: 2 | J19: 4 | K19: 10 | L19: 0.8 | M19: 0.9
A20: 16 | B20: {=ROUND('Tuning'!$B$27*POWER('Tuning'!$B$28,A20-1),0)} | C20: {=C19+B20} | D20: =ROUND(C20/Tuning!$B$26,1) | E20: Long Arms III: pick up chests and med kits from 6 studs away | F20: 20 | G20: 0.7 | H20: Yes | I20: 2 | J20: 6 | K20: 10 | L20: 0.8 | M20: 0.9
A21: 17 | B21: {=ROUND('Tuning'!$B$27*POWER('Tuning'!$B$28,A21-1),0)} | C21: {=C20+B21} | D21: =ROUND(C21/Tuning!$B$26,1) | E21: First Aid III: heal 15 more HP when a round is cleared | F21: 20 | G21: 0.7 | H21: Yes | I21: 2 | J21: 6 | K21: 15 | L21: 0.8 | M21: 0.9
A22: 18 | B22: {=ROUND('Tuning'!$B$27*POWER('Tuning'!$B$28,A22-1),0)} | C22: {=C21+B22} | D22: =ROUND(C22/Tuning!$B$26,1) | E22: Back in Action III: respawn 30% sooner | F22: 20 | G22: 0.7 | H22: Yes | I22: 2 | J22: 6 | K22: 15 | L22: 0.7 | M22: 0.9
... A24: 20 | B24: {=ROUND('Tuning'!$B$27*POWER('Tuning'!$B$28,A24-1),0)} | C24: {=C23+B24} | D24: =ROUND(C24/Tuning!$B$26,1) | E24: Mastery skin (gold gun), and this hero's second upgrade path can reach tier 3 | F24: 20 | G24: 0.7 | H24: Yes | I24: 3 | J24: 6 | K24: 15 | L24: 0.7 | M24: 0.85
A26: 'Matches to earn' assumes an average run reaching round 25.

Sheet Enemies
A1: DINOSAURS — each tier is its own species
A2: Base HP is the species' total HP across all its sizes. A hit that empties a size shrinks the dino one size (same species, HP split evenly across sizes); the smallest size dies. Keys stay internal.
A4: Key | B4: Enemy | C4: Base HP | D4: Scaled HP | E4: Speed x | F4: Splits into | G4: Split count | H4: Effective HP | I4: Cash value | J4: Flying | K4: Note | L4: Armored | M4: Boss | N4: Sizes | O4: Melee name | P4: Melee damage | Q4: Melee every (s) | R4: Melee reach (studs) | S4: Ranged name | T4: Ranged damage | U4: Ranged every (s) | V4: Ranged reach (studs) | W4: Projectile speed (studs/s) | X4: Impact radius (studs) | Y4: Break resist
A5: HUSK | B5: Compy | C5: 1 | D5: {=ROUND(C5*'Tuning'!$B$16,1)} | E5: 1 | F5: — | G5: 0 | H5: {=D5} | I5: {=ROUND(H5*'Tuning'!$B$8,0)} | J5: No | K5: Tiny pack hunter. The baseline. | L5: No | M5: No | N5: 1 | O5: Nip | P5: 2 | Q5: 1 | R5: 8 | T5: 0 | U5: 0 | V5: 0 | W5: 0 | X5: 0 | Y5: 0
A6: BRUTE | B6: Raptor | C6: 3 | D6: {=ROUND(C6*'Tuning'!$B$16,1)} | E6: 1.2 | F6: — | G6: 0 | H6: {=D6+G6*H5} | I6: {=ROUND(H6*'Tuning'!$B$8,0)} | J6: No | L6: No | M6: No | N6: 2 | O6: Slash | P6: 4 | Q6: 1.2 | R6: 9 | T6: 0 | U6: 0 | V6: 0 | W6: 0 | X6: 0 | Y6: 0
A7: SHIELD | B7: Pachycephalosaurus | C7: 8 | D7: {=ROUND(C7*'Tuning'!$B$16,1)} | E7: 1 | F7: — | G7: 0 | H7: {=D7+G7*H6} | I7: {=ROUND(H7*'Tuning'!$B$8,0)} | J7: No | K7: Head-butter. | L7: No | M7: No | N7: 3 | O7: Head-Butt | P7: 6 | Q7: 1.5 | R7: 9 | S7: Skull Toss | T7: 3 | U7: 8 | V7: 22 | W7: 40 | X7: 3 | Y7: 0
A8: ARMOR | B8: Ankylosaurus | C8: 19 | D8: {=ROUND(C8*'Tuning'!$B$16,1)} | E8: 0.8 | F8: — | G8: 0 | H8: {=D8+G8*H7} | I8: {=ROUND(H8*'Tuning'!$B$8,0)} | J8: No | K8: Armoured: needs armour-piercing (or a stripping Tranq) to hurt. | L8: Yes | M8: No | N8: 3 | O8: Tail Club | P8: 10 | Q8: 2 | R8: 10 | S8: Spike Flick | T8: 4 | U8: 8 | V8: 20 | W8: 50 | X8: 3 | Y8: 1
A9: STORM | B9: Gallimimus | C9: 61 | D9: {=ROUND(C9*'Tuning'!$B$16,1)} | E9: 1.4 | F9: — | G9: 0 | H9: {=D9+G9*H8} | I9: {=ROUND(H9*'Tuning'!$B$8,0)} | J9: No | K9: Fast. Slows matter. | L9: No | M9: No | N9: 3 | O9: Kick | P9: 6 | Q9: 1 | R9: 9 | S9: Gravel Spray | T9: 5 | U9: 6.5 | V9: 25 | W9: 70 | X9: 3 | Y9: 0
A10: LLAMA | B10: Pteranodon | C10: 20 | D10: {=ROUND(C10*'Tuning'!$B$16,1)} | E10: 0.9 | F10: — | G10: 0 | H10: {=D10+G10*H7} | I10: {=ROUND(H10*'Tuning'!$B$8,0)} | J10: Yes | K10: Flying. The Mortar Pit cannot hit it. | L10: No | M10: No | N10: 3 | P10: 0 | Q10: 0 | R10: 0 | S10: Stone Drop | T10: 5 | U10: 6.5 | V10: 18 | W10: 35 | X10: 4 | Y10: 0
A11: ZEP | B11: Triceratops | C11: 280 | D11: {=ROUND(C11*'Tuning'!$B$16,1)} | E11: 0.5 | F11: — | G11: 0 | H11: {=D11+G11*H10} | I11: {=ROUND(H11*'Tuning'!$B$8,0)} | J11: No | K11: Ground boss. | L11: No | M11: Yes | N11: 4 | O11: Gore | P11: 25 | Q11: 2 | R11: 12 | S11: Horn Toss | T11: 20 | U11: 5 | V11: 30 | W11: 45 | X11: 5 | Y11: 1
A12: BARGE | B12: T-Rex | C12: 1820 | D12: {=ROUND(C12*'Tuning'!$B$16,1)} | E12: 0.4 | F12: — | G12: 0 | H12: {=D12+G12*H11} | I12: {=ROUND(H12*'Tuning'!$B$8,0)} | J12: No | K12: Ground boss. Round 40 finale. | L12: No | M12: Yes | N12: 5 | O12: Chomp | P12: 50 | Q12: 2.5 | R12: 14 | S12: Bone Spit | T12: 35 | U12: 6 | V12: 35 | W12: 35 | X12: 8 | Y12: 2
A14: EFFECTIVE HP
A15: Effective HP: total damage to clear one dino, every size included.
A16: Melee: every dino bites the nearest tower or hunter within reach (studs sideways from the track), dealing damage x size/sizes x Difficulty Dino damage x. The Pteranodon only has a ranged attack.
A17: Ranged: mid and high tiers also throw something at the nearest tower or hunter in reach. It flies in a straight line (no homing) to where the target was, and hurts every hunter and standing tower within the impact radius. Values are at the dino's largest size, on Easy.

Sheet Rounds
A1: ROUND TABLE — 40 rounds
A2: Blue counts are the designer's call, not a formula. Everything to the right of them is derived.
A4: Round | B4: Compy | C4: Raptor | D4: Pachy | E4: Ankylosaurus | F4: Gallimimus | G4: Pteranodon | H4: Triceratops | I4: T-Rex | J4: Enemies | K4: HP multiplier | L4: Spawn gap (s) | M4: Total EHP | N4: Round length (s) | O4: Required DPS | P4: Kill income | Q4: Round bonus | R4: Round income | S4: Cumulative cash
A5: 1 | B5: 17 | C5: 7 | D5: 0 | E5: 0 | F5: 0 | G5: 0 | H5: 0 | I5: 0 | J5: {=SUM(B5:I5)} | K5: {=ROUND(POWER('Tuning'!$B$17,A5-1),3)} | L5: 1.19 | M5: {=ROUND((B5*'Enemies'!$H$5+C5*'Enemies'!$H$6+D5*'Enemies'!$H$7+E5*'Enemies'!$H$8+F5*'Enemies'!$H$9+G5*'Enemies'!$H$10+H5*'Enemies'!$H$11+I5*'Enemies'!$H$12)*K5,0)} | N5: {=ROUND(J5*L5+14,0)} | O5: {=IF(N5=0,0,ROUND(M5/N5,1))} | P5: {=ROUND(M5*'Tuning'!$B$8,0)} | Q5: {=ROUND('Tuning'!$B$9+'Tuning'!$B$10*A5,0)} | R5: {=P5+Q5} | S5: {='Tuning'!$B$6+R5}
A6: 2 | B6: 20 | C6: 8 | D6: 0 | E6: 0 | F6: 0 | G6: 0 | H6: 0 | I6: 0 | J6: {=SUM(B6:I6)} | K6: {=ROUND(POWER('Tuning'!$B$17,A6-1),3)} | L6: 1.17 | M6: {=ROUND((B6*'Enemies'!$H$5+C6*'Enemies'!$H$6+D6*'Enemies'!$H$7+E6*'Enemies'!$H$8+F6*'Enemies'!$H$9+G6*'Enemies'!$H$10+H6*'Enemies'!$H$11+I6*'Enemies'!$H$12)*K6,0)} | N6: {=ROUND(J6*L6+14,0)} | O6: {=IF(N6=0,0,ROUND(M6/N6,1))} | P6: {=ROUND(M6*'Tuning'!$B$8,0)} | Q6: {=ROUND('Tuning'!$B$9+'Tuning'!$B$10*A6,0)} | R6: {=P6+Q6} | S6: {=S5+R6}
A7: 3 | B7: 23 | C7: 9 | D7: 0 | E7: 0 | F7: 0 | G7: 0 | H7: 0 | I7: 0 | J7: {=SUM(B7:I7)} | K7: {=ROUND(POWER('Tuning'!$B$17,A7-1),3)} | L7: 1.16 | M7: {=ROUND((B7*'Enemies'!$H$5+C7*'Enemies'!$H$6+D7*'Enemies'!$H$7+E7*'Enemies'!$H$8+F7*'Enemies'!$H$9+G7*'Enemies'!$H$10+H7*'Enemies'!$H$11+I7*'Enemies'!$H$12)*K7,0)} | N7: {=ROUND(J7*L7+14,0)} | O7: {=IF(N7=0,0,ROUND(M7/N7,1))} | P7: {=ROUND(M7*'Tuning'!$B$8,0)} | Q7: {=ROUND('Tuning'!$B$9+'Tuning'!$B$10*A7,0)} | R7: {=P7+Q7} | S7: {=S6+R7}
A8: 4 | B8: 26 | C8: 10 | D8: 0 | E8: 0 | F8: 0 | G8: 0 | H8: 0 | I8: 0 | J8: {=SUM(B8:I8)} | K8: {=ROUND(POWER('Tuning'!$B$17,A8-1),3)} | L8: 1.14 | M8: {=ROUND((B8*'Enemies'!$H$5+C8*'Enemies'!$H$6+D8*'Enemies'!$H$7+E8*'Enemies'!$H$8+F8*'Enemies'!$H$9+G8*'Enemies'!$H$10+H8*'Enemies'!$H$11+I8*'Enemies'!$H$12)*K8,0)} | N8: {=ROUND(J8*L8+14,0)} | O8: {=IF(N8=0,0,ROUND(M8/N8,1))} | P8: {=ROUND(M8*'Tuning'!$B$8,0)} | Q8: {=ROUND('Tuning'!$B$9+'Tuning'!$B$10*A8,0)} | R8: {=P8+Q8} | S8: {=S7+R8}
A9: 5 | B9: 29 | C9: 11 | D9: 0 | E9: 0 | F9: 0 | G9: 0 | H9: 0 | I9: 0 | J9: {=SUM(B9:I9)} | K9: {=ROUND(POWER('Tuning'!$B$17,A9-1),3)} | L9: 1.13 | M9: {=ROUND((B9*'Enemies'!$H$5+C9*'Enemies'!$H$6+D9*'Enemies'!$H$7+E9*'Enemies'!$H$8+F9*'Enemies'!$H$9+G9*'Enemies'!$H$10+H9*'Enemies'!$H$11+I9*'Enemies'!$H$12)*K9,0)} | N9: {=ROUND(J9*L9+14,0)} | O9: {=IF(N9=0,0,ROUND(M9/N9,1))} | P9: {=ROUND(M9*'Tuning'!$B$8,0)} | Q9: {=ROUND('Tuning'!$B$9+'Tuning'!$B$10*A9,0)} | R9: {=P9+Q9} | S9: {=S8+R9}
A10: 6 | B10: 32 | C10: 12 | D10: 0 | E10: 0 | F10: 0 | G10: 0 | H10: 0 | I10: 0 | J10: {=SUM(B10:I10)} | K10: {=ROUND(POWER('Tuning'!$B$17,A10-1),3)} | L10: 1.12 | M10: {=ROUND((B10*'Enemies'!$H$5+C10*'Enemies'!$H$6+D10*'Enemies'!$H$7+E10*'Enemies'!$H$8+F10*'Enemies'!$H$9+G10*'Enemies'!$H$10+H10*'Enemies'!$H$11+I10*'Enemies'!$H$12)*K10,0)} | N10: {=ROUND(J10*L10+14,0)} | O10: {=IF(N10=0,0,ROUND(M10/N10,1))} | P10: {=ROUND(M10*'Tuning'!$B$8,0)} | Q10: {=ROUND('Tuning'!$B$9+'Tuning'!$B$10*A10,0)} | R10: {=P10+Q10} | S10: {=S9+R10}
A11: 7 | B11: 35 | C11: 13 | D11: 2 | E11: 0 | F11: 0 | G11: 0 | H11: 0 | I11: 0 | J11: {=SUM(B11:I11)} | K11: {=ROUND(POWER('Tuning'!$B$17,A11-1),3)} | L11: 1.1 | M11: {=ROUND((B11*'Enemies'!$H$5+C11*'Enemies'!$H$6+D11*'Enemies'!$H$7+E11*'Enemies'!$H$8+F11*'Enemies'!$H$9+G11*'Enemies'!$H$10+H11*'Enemies'!$H$11+I11*'Enemies'!$H$12)*K11,0)} | N11: {=ROUND(J11*L11+14,0)} | O11: {=IF(N11=0,0,ROUND(M11/N11,1))} | P11: {=ROUND(M11*'Tuning'!$B$8,0)} | Q11: {=ROUND('Tuning'!$B$9+'Tuning'!$B$10*A11,0)} | R11: {=P11+Q11} | S11: {=S10+R11}
A12: 8 | B12: 37 | C12: 15 | D12: 4 | E12: 0 | F12: 0 | G12: 0 | H12: 0 | I12: 0 | J12: {=SUM(B12:I12)} | K12: {=ROUND(POWER('Tuning'!$B$17,A12-1),3)} | L12: 1.09 | M12: {=ROUND((B12*'Enemies'!$H$5+C12*'Enemies'!$H$6+D12*'Enemies'!$H$7+E12*'Enemies'!$H$8+F12*'Enemies'!$H$9+G12*'Enemies'!$H$10+H12*'Enemies'!$H$11+I12*'Enemies'!$H$12)*K12,0)} | N12: {=ROUND(J12*L12+14,0)} | O12: {=IF(N12=0,0,ROUND(M12/N12,1))} | P12: {=ROUND(M12*'Tuning'!$B$8,0)} | Q12: {=ROUND('Tuning'!$B$9+'Tuning'!$B$10*A12,0)} | R12: {=P12+Q12} | S12: {=S11+R12}
A13: 9 | B13: 40 | C13: 16 | D13: 6 | E13: 0 | F13: 0 | G13: 1 | H13: 0 | I13: 0 | J13: {=SUM(B13:I13)} | K13: {=ROUND(POWER('Tuning'!$B$17,A13-1),3)} | L13: 1.07 | M13: {=ROUND((B13*'Enemies'!$H$5+C13*'Enemies'!$H$6+D13*'Enemies'!$H$7+E13*'Enemies'!$H$8+F13*'Enemies'!$H$9+G13*'Enemies'!$H$10+H13*'Enemies'!$H$11+I13*'Enemies'!$H$12)*K13,0)} | N13: {=ROUND(J13*L13+14,0)} | O13: {=IF(N13=0,0,ROUND(M13/N13,1))} | P13: {=ROUND(M13*'Tuning'!$B$8,0)} | Q13: {=ROUND('Tuning'!$B$9+'Tuning'!$B$10*A13,0)} | R13: {=P13+Q13} | S13: {=S12+R13}
A14: 10 | B14: 43 | C14: 17 | D14: 9 | E14: 2 | F14: 0 | G14: 2 | H14: 0 | I14: 0 | J14: {=SUM(B14:I14)} | K14: {=ROUND(POWER('Tuning'!$B$17,A14-1),3)} | L14: 1.06 | M14: {=ROUND((B14*'Enemies'!$H$5+C14*'Enemies'!$H$6+D14*'Enemies'!$H$7+E14*'Enemies'!$H$8+F14*'Enemies'!$H$9+G14*'Enemies'!$H$10+H14*'Enemies'!$H$11+I14*'Enemies'!$H$12)*K14,0)} | N14: {=ROUND(J14*L14+14,0)} | O14: {=IF(N14=0,0,ROUND(M14/N14,1))} | P14: {=ROUND(M14*'Tuning'!$B$8,0)} | Q14: {=ROUND('Tuning'!$B$9+'Tuning'!$B$10*A14,0)} | R14: {=P14+Q14} | S14: {=S13+R14}
A15: 11 | B15: 19 | C15: 16 | D15: 14 | E15: 6 | F15: 0 | G15: 5 | H15: 0 | I15: 0 | J15: {=SUM(B15:I15)} | K15: {=ROUND(POWER('Tuning'!$B$17,A15-1),3)} | L15: 1.05 | M15: {=ROUND((B15*'Enemies'!$H$5+C15*'Enemies'!$H$6+D15*'Enemies'!$H$7+E15*'Enemies'!$H$8+F15*'Enemies'!$H$9+G15*'Enemies'!$H$10+H15*'Enemies'!$H$11+I15*'Enemies'!$H$12)*K15,0)} | N15: {=ROUND(J15*L15+14,0)} | O15: {=IF(N15=0,0,ROUND(M15/N15,1))} | P15: {=ROUND(M15*'Tuning'!$B$8,0)} | Q15: {=ROUND('Tuning'!$B$9+'Tuning'!$B$10*A15,0)} | R15: {=P15+Q15} | S15: {=S14+R15}
A16: 12 | B16: 20 | C16: 17 | D16: 16 | E16: 7 | F16: 0 | G16: 5 | H16: 0 | I16: 0 | J16: {=SUM(B16:I16)} | K16: {=ROUND(POWER('Tuning'!$B$17,A16-1),3)} | L16: 1.03 | M16: {=ROUND((B16*'Enemies'!$H$5+C16*'Enemies'!$H$6+D16*'Enemies'!$H$7+E16*'Enemies'!$H$8+F16*'Enemies'!$H$9+G16*'Enemies'!$H$10+H16*'Enemies'!$H$11+I16*'Enemies'!$H$12)*K16,0)} | N16: {=ROUND(J16*L16+14,0)} | O16: {=IF(N16=0,0,ROUND(M16/N16,1))} | P16: {=ROUND(M16*'Tuning'!$B$8,0)} | Q16: {=ROUND('Tuning'!$B$9+'Tuning'!$B$10*A16,0)} | R16: {=P16+Q16} | S16: {=S15+R16}
A17: 13 | B17: 22 | C17: 18 | D17: 18 | E17: 9 | F17: 0 | G17: 6 | H17: 0 | I17: 0 | J17: {=SUM(B17:I17)} | K17: {=ROUND(POWER('Tuning'!$B$17,A17-1),3)} | L17: 1.02 | M17: {=ROUND((B17*'Enemies'!$H$5+C17*'Enemies'!$H$6+D17*'Enemies'!$H$7+E17*'Enemies'!$H$8+F17*'Enemies'!$H$9+G17*'Enemies'!$H$10+H17*'Enemies'!$H$11+I17*'Enemies'!$H$12)*K17,0)} | N17: {=ROUND(J17*L17+14,0)} | O17: {=IF(N17=0,0,ROUND(M17/N17,1))} | P17: {=ROUND(M17*'Tuning'!$B$8,0)} | Q17: {=ROUND('Tuning'!$B$9+'Tuning'!$B$10*A17,0)} | R17: {=P17+Q17} | S17: {=S16+R17}
... A44: 40 | B44: 0 | C44: 16 | D44: 26 | E44: 31 | F44: 31 | G44: 18 | H44: 8 | I44: 1 | J44: {=SUM(B44:I44)} | K44: {=ROUND(POWER('Tuning'!$B$17,A44-1),3)} | L44: 0.64 | M44: {=ROUND((B44*'Enemies'!$H$5+C44*'Enemies'!$H$6+D44*'Enemies'!$H$7+E44*'Enemies'!$H$8+F44*'Enemies'!$H$9+G44*'Enemies'!$H$10+H44*'Enemies'!$H$11+I44*'Enemies'!$H$12)*K44,0)} | N44: {=ROUND(J44*L44+14,0)} | O44: {=IF(N44=0,0,ROUND(M44/N44,1))} | P44: {=ROUND(M44*'Tuning'!$B$8,0)} | Q44: {=ROUND('Tuning'!$B$9+'Tuning'!$B$10*A44,0)} | R44: {=P44+Q44} | S44: {=S43+R44}
A46: Shaded rows are band transitions, where a new enemy type enters and difficulty spikes. That sawtooth is intentional.
A47: Enemy counts plateau at 130 because UEFN, not design, sets the ceiling. Late difficulty comes from the HP multiplier instead — the same reason BTD6 late rounds are a few BADs and not two thousand bloons.
A48: Round length assumes spawn gap x enemy count plus 14s of clear time: measured 2026-09-28, a round ends ~14s after its last spawn when nothing leaks. A dino that leaks walks the whole track (~44s), which only matters for leaks. Rough, but consistent across rounds, which is what matters for comparison.

Sheet Difficulty
A1: DIFFICULTY — Easy is the baseline; every other level scales from it
A2: Chosen before round 1. Player-count scaling (Tuning, CO-OP) applies on top.
A4: Difficulty | B4: Enemy HP x | C4: Enemy count x | D4: Enemy speed x | E4: Promote chance | F4: Cash x | G4: Starting lives | H4: Note | I4: Clear reward (amber) | J4: Dino damage x | K4: Starting cash | L4: Tower damage x | M4: Hero damage x | N4: Clear XP
A5: Easy | B5: 1 | C5: 1 | D5: 1 | E5: 0 | F5: 1 | G5: 40 | H5: The baseline. Current balance. | I5: 50 | J5: 1 | K5: 450 | L5: 1 | M5: 1 | N5: 500
A6: Normal | B6: 1.25 | C6: 1.3 | D6: 1.05 | E6: 0.1 | F6: 0.9 | G6: 30 | H6: 10% of enemies spawn one tier tougher. | I6: 100 | J6: 1.25 | K6: 450 | L6: 1 | M6: 1 | N6: 1000
A7: Hard | B7: 1.6 | C7: 1.7 | D7: 1.1 | E7: 0.2 | F7: 0.8 | G7: 20 | I7: 150 | J7: 1.6 | K7: 850 | L7: 1 | M7: 1 | N7: 1500
A8: Chaos | B8: 2.2 | C8: 2.5 | D8: 1.2 | E8: 0.35 | F8: 0.75 | G8: 10 | H8: Meant for big lobbies. | I8: 200 | J8: 2.2 | K8: 450 | L8: 0.6 | M8: 1.5 | N8: 2000
A11: Enemy count x raises density: the round's spawn gap shrinks by the same factor, so rounds get busier, not longer.
A12: Promote chance: each spawn has this chance to become the next ground species up (Compy > Raptor > Pachy > Ankylosaurus > Gallimimus). Flyers and bosses are never promoted.
A13: Cash x scales kill income and the round bonus.

Sheet Balance Check
A1: BALANCE CHECK — is each round actually winnable?
A2: An economy smoke test, not a difficulty simulator. Open it after every change to Tuning.
A4: Round | B4: Required DPS | C4: Ref tier | D4: Cost per DPS | E4: Cash needed | F4: Cumulative cash | G4: Cash in towers | H4: Affordability | I4: Status
A5: 1 | B5: {='Rounds'!O5} | C5: {=MIN(5,A5/'Tuning'!$B$32)} | D5: =ROUND('Towers'!$C$13*POWER('Tuning'!$B$12/'Tuning'!$B$13,C5),1) | E5: {=ROUND(B5*D5/'Tuning'!$B$31,0)} | F5: {='Rounds'!S5} | G5: {=ROUND(F5*'Tuning'!$B$30,0)} | H5: {=IF(E5=0,0,G5/E5)} | I5: {=IF(H5<1,"TIGHT",IF(H5<2,"OK","EASY"))}
A6: 2 | B6: {='Rounds'!O6} | C6: {=MIN(5,A6/'Tuning'!$B$32)} | D6: =ROUND('Towers'!$C$13*POWER('Tuning'!$B$12/'Tuning'!$B$13,C6),1) | E6: {=ROUND(B6*D6/'Tuning'!$B$31,0)} | F6: {='Rounds'!S6} | G6: {=ROUND(F6*'Tuning'!$B$30,0)} | H6: {=IF(E6=0,0,G6/E6)} | I6: {=IF(H6<1,"TIGHT",IF(H6<2,"OK","EASY"))}
A7: 3 | B7: {='Rounds'!O7} | C7: {=MIN(5,A7/'Tuning'!$B$32)} | D7: =ROUND('Towers'!$C$13*POWER('Tuning'!$B$12/'Tuning'!$B$13,C7),1) | E7: {=ROUND(B7*D7/'Tuning'!$B$31,0)} | F7: {='Rounds'!S7} | G7: {=ROUND(F7*'Tuning'!$B$30,0)} | H7: {=IF(E7=0,0,G7/E7)} | I7: {=IF(H7<1,"TIGHT",IF(H7<2,"OK","EASY"))}
A8: 4 | B8: {='Rounds'!O8} | C8: {=MIN(5,A8/'Tuning'!$B$32)} | D8: =ROUND('Towers'!$C$13*POWER('Tuning'!$B$12/'Tuning'!$B$13,C8),1) | E8: {=ROUND(B8*D8/'Tuning'!$B$31,0)} | F8: {='Rounds'!S8} | G8: {=ROUND(F8*'Tuning'!$B$30,0)} | H8: {=IF(E8=0,0,G8/E8)} | I8: {=IF(H8<1,"TIGHT",IF(H8<2,"OK","EASY"))}
A9: 5 | B9: {='Rounds'!O9} | C9: {=MIN(5,A9/'Tuning'!$B$32)} | D9: =ROUND('Towers'!$C$13*POWER('Tuning'!$B$12/'Tuning'!$B$13,C9),1) | E9: {=ROUND(B9*D9/'Tuning'!$B$31,0)} | F9: {='Rounds'!S9} | G9: {=ROUND(F9*'Tuning'!$B$30,0)} | H9: {=IF(E9=0,0,G9/E9)} | I9: {=IF(H9<1,"TIGHT",IF(H9<2,"OK","EASY"))}
A10: 6 | B10: {='Rounds'!O10} | C10: {=MIN(5,A10/'Tuning'!$B$32)} | D10: =ROUND('Towers'!$C$13*POWER('Tuning'!$B$12/'Tuning'!$B$13,C10),1) | E10: {=ROUND(B10*D10/'Tuning'!$B$31,0)} | F10: {='Rounds'!S10} | G10: {=ROUND(F10*'Tuning'!$B$30,0)} | H10: {=IF(E10=0,0,G10/E10)} | I10: {=IF(H10<1,"TIGHT",IF(H10<2,"OK","EASY"))}
A11: 7 | B11: {='Rounds'!O11} | C11: {=MIN(5,A11/'Tuning'!$B$32)} | D11: =ROUND('Towers'!$C$13*POWER('Tuning'!$B$12/'Tuning'!$B$13,C11),1) | E11: {=ROUND(B11*D11/'Tuning'!$B$31,0)} | F11: {='Rounds'!S11} | G11: {=ROUND(F11*'Tuning'!$B$30,0)} | H11: {=IF(E11=0,0,G11/E11)} | I11: {=IF(H11<1,"TIGHT",IF(H11<2,"OK","EASY"))}
A12: 8 | B12: {='Rounds'!O12} | C12: {=MIN(5,A12/'Tuning'!$B$32)} | D12: =ROUND('Towers'!$C$13*POWER('Tuning'!$B$12/'Tuning'!$B$13,C12),1) | E12: {=ROUND(B12*D12/'Tuning'!$B$31,0)} | F12: {='Rounds'!S12} | G12: {=ROUND(F12*'Tuning'!$B$30,0)} | H12: {=IF(E12=0,0,G12/E12)} | I12: {=IF(H12<1,"TIGHT",IF(H12<2,"OK","EASY"))}
A13: 9 | B13: {='Rounds'!O13} | C13: {=MIN(5,A13/'Tuning'!$B$32)} | D13: =ROUND('Towers'!$C$13*POWER('Tuning'!$B$12/'Tuning'!$B$13,C13),1) | E13: {=ROUND(B13*D13/'Tuning'!$B$31,0)} | F13: {='Rounds'!S13} | G13: {=ROUND(F13*'Tuning'!$B$30,0)} | H13: {=IF(E13=0,0,G13/E13)} | I13: {=IF(H13<1,"TIGHT",IF(H13<2,"OK","EASY"))}
A14: 10 | B14: {='Rounds'!O14} | C14: {=MIN(5,A14/'Tuning'!$B$32)} | D14: =ROUND('Towers'!$C$13*POWER('Tuning'!$B$12/'Tuning'!$B$13,C14),1) | E14: {=ROUND(B14*D14/'Tuning'!$B$31,0)} | F14: {='Rounds'!S14} | G14: {=ROUND(F14*'Tuning'!$B$30,0)} | H14: {=IF(E14=0,0,G14/E14)} | I14: {=IF(H14<1,"TIGHT",IF(H14<2,"OK","EASY"))}
A15: 11 | B15: {='Rounds'!O15} | C15: {=MIN(5,A15/'Tuning'!$B$32)} | D15: =ROUND('Towers'!$C$13*POWER('Tuning'!$B$12/'Tuning'!$B$13,C15),1) | E15: {=ROUND(B15*D15/'Tuning'!$B$31,0)} | F15: {='Rounds'!S15} | G15: {=ROUND(F15*'Tuning'!$B$30,0)} | H15: {=IF(E15=0,0,G15/E15)} | I15: {=IF(H15<1,"TIGHT",IF(H15<2,"OK","EASY"))}
A16: 12 | B16: {='Rounds'!O16} | C16: {=MIN(5,A16/'Tuning'!$B$32)} | D16: =ROUND('Towers'!$C$13*POWER('Tuning'!$B$12/'Tuning'!$B$13,C16),1) | E16: {=ROUND(B16*D16/'Tuning'!$B$31,0)} | F16: {='Rounds'!S16} | G16: {=ROUND(F16*'Tuning'!$B$30,0)} | H16: {=IF(E16=0,0,G16/E16)} | I16: {=IF(H16<1,"TIGHT",IF(H16<2,"OK","EASY"))}
